Workbook
Name Cash_Position: 'Portfolio Statement'!$A$5:$D$14
Name tbl_transactions_Clean1: Transaction_Clean!$A$1:$Q$30

Sheet Dashboard

Sheet Analysis

Sheet Portfolio Statement
A1: Portfolio Statement | J1: {=_xlfn._xlws.SORT(_xlfn.UNIQUE(_xlfn._xlws.FILTER(tbl__Clean[Asset],((tbl__Clean[Action]="BUY")+(tbl__Clean[Action]="SELL"))*(tbl__Clean[Asset]<>""))))} -> KCG
J2: PTT
J3: SIRI
A4: Cash Position
A5: Metric | B5: Value | C5: Transaction Count | D5: คำอธิบาย
A6: Current Bank Cash | B6: {=_xlfn.XLOOKUP(TRUE,tbl__Clean[Cash]<>"",tbl__Clean[Cash],0,0,-1)} -> 23 | C6: - | D6: ยอดเงินที่เหลืออยู่ธนาคารสำหรับลงทุนตอนนี้
A7: Current Broker Cash | B7: {=_xlfn.XLOOKUP(TRUE,tbl__Clean[Cash Balance]<>"",tbl__Clean[Cash Balance],0,0,-1)} -> 16489.13 | C7: - | D7: ยอดเงินที่เหลืออยู่บัญชีทุกโบรเกอร์ตอนนี้
A8: Total Deposit | B8: =SUMIFS(tbl__Clean[Amount],tbl__Clean[Action],"DEPOSIT") -> 20000 | C8: =COUNTIF(tbl__Clean[Action],"DEPOSIT") -> 6 | D8: ยอดเงินใหม่ที่ฝากเข้าธนาคาร
A9: Total Withdrawal | B9: =SUMIFS(tbl__Clean[Amount],tbl__Clean[Action],"WITHDRAW") -> 0 | C9: =COUNTIF(tbl__Clean[Action],"WITHDRAW") -> 0 | D9: ยอดเงินทีถอนออกจากธนาคาร
A10: Net External Cash Flow | B10: =B8-B9 -> 20000 | C10: - | D10: เงินที่ใส่เข้ามาในธนาคาร หักด้วยเงินที่นำออกจากธนาคารสำหรับลงทุน
A11: Total Dividend | B11: =SUMIFS(tbl__Clean[Net Amount],tbl__Clean[Action],"DIVIDEND") -> 319.73 | C11: =COUNTIF(tbl__Clean[Action],"DIVIDEND") -> 4 | D11: เงินปันผลทั้งหมดที่ได้รับ หลังจากหักภาษี
A12: Total Buy Amount | B12: =SUMIFS(tbl__Clean[Net Amount],tbl__Clean[Action],"BUY") -> 8003.03 | C12: =COUNTIF(tbl__Clean[Action],"BUY") -> 5 | D12: ยอดรวมเงินการทำธุระกรรม"ซื้อ"ทั้งหมด
A13: Total Sell Amount | B13: =SUMIFS(tbl__Clean[Net Amount],tbl__Clean[Action],"SELL") -> 4171.34 | C13: =COUNTIF(tbl__Clean[Action],"SELL") -> 1 | D13: ยอดรวมเงินการทำธุระกรรม"ขาย"ทั้งหมด
A14: Total Transaction Costs | B14: =SUM(tbl__Clean[Commission])+SUM(tbl__Clean[Fee])+SUM(tbl__Clean[VAT]) -> 34.76 | C14: =C12+C13 -> 6 | D14: ค่าใช้จ่าเพิ่มเติมจาการ ซื้อขายหุ้นได้แก่ ค่าธรรมเนียมโบกเกอร์,ค่าธรรมเนียมSET,ภาษี7%
A18: Holdings Position
A19: Asset | B19: Total Buy Quantity | C19: Total Sell Quantity | D19: Current Quantity | E19: Total Buy Cost | F19: Total Sell Cost | G19: Status
A20: =J1 -> KCG
A21: =J2 -> PTT
A22: =J3 -> SIRI
A23: =J4 -> 0
A24: =J5 -> 0
A25: =J6 -> 0
A26: =J7 -> 0
A27: =J8 -> 0

Sheet Transaction_Clean
A1: Transaction ID | B1: Date | C1: Market | D1: Account | E1: Sequence | F1: Asset | G1: Action | H1: Amount | I1: Quantity | J1: Price | K1: Commission | L1: Fee | M1: VAT | N1: Gross Amount | O1: Net Amount | P1: Cash | Q1: Cash Balance
A2: =tbl_transactions[[#This Row],[Transaction ID]] -> TH-001 | B2: =tbl_transactions[[#This Row],[Date]] -> 45873 | C2: =tbl_transactions[[#This Row],[Market]] -> 0 | D2: =tbl_transactions[[#This Row],[Account]] -> 0 | E2: =tbl_transactions[[#This Row],[Sequence]] -> 1 | F2: =tbl_transactions[[#This Row],[Asset]] -> cash | G2: =tbl_transactions[[#This Row],[Action]] -> DEPOSIT | H2: =Transaction_Log!H2 -> 4000 | I2: =tbl_transactions[[#This Row],[Quantity]] -> 0 | J2: =tbl_transactions[[#This Row],[Price]] -> 0 | K2: =IF(G2<>0,IF(OR(G2="BUY",G2="SELL"),ROUND((I2*J2)*0.00075,2),0),"") -> 0 | L2: =IF(G2<>0,IF(OR(G2="BUY",G2="SELL"),ROUND((I2*J2)*0.00007,2),0),"") -> 0 | M2: =IF(G2<>0,IF(AND(K2<>"",L2<>"",G2<>"DIVIDEND"),ROUND((K2+L2)*0.07,2),ROUND(H2*0.07,2)),"") -> 0 | N2: =IF(F2="cash",0,IF(OR(G2="BUY",G2="SELL"),I2*J2,"")) -> 0 | O2: =IF(G2<>0,IF(AND(I2<>"",J2<>"",K2<>"",L2<>"",G2="BUY"),(I2*J2)+K2+L2+M2,IF(AND(I2<>"",J2<>"",K2<>"",L2<>"",G2="SELL"),(I2*J2)-(K2+L2+M2),IF(AND(I2<>"",J2<>"",K2<>"",L2<>"",G2="DIVIDEND"),H2-M2,H2))),"") -> 4000 | P2: =H2 -> 4000 | Q2: 0.02
A3: =tbl_transactions[[#This Row],[Transaction ID]] -> TH-002 | B3: =tbl_transactions[[#This Row],[Date]] -> 45877 | C3: =tbl_transactions[[#This Row],[Market]] -> 0 | D3: =tbl_transactions[[#This Row],[Account]] -> 1383357 | E3: =tbl_transactions[[#This Row],[Sequence]] -> 2 | F3: =tbl_transactions[[#This Row],[Asset]] -> cash | G3: =tbl_transactions[[#This Row],[Action]] -> TRANSFER_TO_BROKER | H3: =Transaction_Log!H3 -> 4000 | I3: =tbl_transactions[[#This Row],[Quantity]] -> 0 | J3: =tbl_transactions[[#This Row],[Price]] -> 0 | K3: =IF(G3<>0,IF(OR(G3="BUY",G3="SELL"),ROUND((I3*J3)*0.00075,2),0),"") -> 0 | L3: =IF(G3<>0,IF(OR(G3="BUY",G3="SELL"),ROUND((I3*J3)*0.00007,2),0),"") -> 0 | M3: =IF(G3<>0,IF(AND(K3<>"",L3<>"",G3<>"DIVIDEND"),ROUND((K3+L3)*0.07,2),ROUND(H3*0.07,2)),"") -> 0 | N3: =IF(F3="cash",0,IF(OR(G3="BUY",G3="SELL"),I3*J3,"")) -> 0 | O3: =IF(G3<>0,IF(AND(I3<>"",J3<>"",K3<>"",L3<>"",G3="BUY"),(I3*J3)+K3+L3+M3,IF(AND(I3<>"",J3<>"",K3<>"",L3<>"",G3="SELL"),(I3*J3)-(K3+L3+M3),IF(AND(I3<>"",J3<>"",K3<>"",L3<>"",G3="DIVIDEND"),H3-M3,H3))),"") -> 4000 | P3: =IF(G3<>0,IF(AND(G3="DEPOSIT",F3="cash"),H3+P2,IF(AND(G3="TRANSFER_TO_BROKER",F3="cash"),P2-H3,IF(AND(G3="DIVIDEND",F3<>""),H3+P2,P2))),"") -> 0 | Q3: =IF(F3<>0,IF(G3<>"",IF(G3="TRANSFER_TO_BROKER",H3+Q2,IF(G3="BUY", Q2-O3,IF(G3="SELL", O3+Q2,IF(G3="TRANSFER_TO_BANK",Q2-H3,Q2)))), ""),"") -> 4000.02
A4: =tbl_transactions[[#This Row],[Transaction ID]] -> TH-003 | B4: =tbl_transactions[[#This Row],[Date]] -> 45877 | C4: =tbl_transactions[[#This Row],[Market]] -> set | D4: =tbl_transactions[[#This Row],[Account]] -> 1383357 | E4: =tbl_transactions[[#This Row],[Sequence]] -> 3 | F4: =tbl_transactions[[#This Row],[Asset]] -> SIRI | G4: =tbl_transactions[[#This Row],[Action]] -> BUY | H4: =Transaction_Log!H4 -> 0 | I4: =tbl_transactions[[#This Row],[Quantity]] -> 300 | J4: =tbl_transactions[[#This Row],[Price]] -> 1.5 | K4: =IF(G4<>0,IF(OR(G4="BUY",G4="SELL"),ROUND((I4*J4)*0.00075,2),0),"") -> 0.34 | L4: =IF(G4<>0,IF(OR(G4="BUY",G4="SELL"),ROUND((I4*J4)*0.00007,2),0),"") -> 0.03 | M4: =IF(G4<>0,IF(AND(K4<>"",L4<>"",G4<>"DIVIDEND"),ROUND((K4+L4)*0.07,2),ROUND(H4*0.07,2)),"") -> 0.03 | N4: =IF(F4="cash",0,IF(OR(G4="BUY",G4="SELL"),I4*J4,"")) -> 450 | O4: =IF(G4<>0,IF(AND(I4<>"",J4<>"",K4<>"",L4<>"",G4="BUY"),(I4*J4)+K4+L4+M4,IF(AND(I4<>"",J4<>"",K4<>"",L4<>"",G4="SELL"),(I4*J4)-(K4+L4+M4),IF(AND(I4<>"",J4<>"",K4<>"",L4<>"",G4="DIVIDEND"),H4-M4,H4))),"") -> 450.4 | P4: =IF(G4<>0,IF(AND(G4="DEPOSIT",F4="cash"),H4+P3,IF(AND(G4="TRANSFER_TO_BROKER",F4="cash"),P3-H4,IF(AND(G4="DIVIDEND",F4<>""),H4+P3,P3))),"") -> 0 | Q4: =IF(F4<>0,IF(G4<>"",IF(G4="TRANSFER_TO_BROKER",H4+Q3,IF(G4="BUY", Q3-O4,IF(G4="SELL", O4+Q3,IF(G4="TRANSFER_TO_BANK",Q3-H4,Q3)))), ""),"") -> 3549.62
A5: =tbl_transactions[[#This Row],[Transaction ID]] -> TH-004 | B5: =tbl_transactions[[#This Row],[Date]] -> 45882 | C5: =tbl_transactions[[#This Row],[Market]] -> set | D5: =tbl_transactions[[#This Row],[Account]] -> 1383357 | E5: =tbl_transactions[[#This Row],[Sequence]] -> 4 | F5: =tbl_transactions[[#This Row],[Asset]] -> PTT | G5: =tbl_transactions[[#This Row],[Action]] -> BUY | H5: =Transaction_Log!H6 -> 0 | I5: =tbl_transactions[[#This Row],[Quantity]] -> 100 | J5: =tbl_transactions[[#This Row],[Price]] -> 32.5 | K5: =IF(G5<>0,IF(OR(G5="BUY",G5="SELL"),ROUND((I5*J5)*0.00075,2),0),"") -> 2.44 | L5: =IF(G5<>0,IF(OR(G5="BUY",G5="SELL"),ROUND((I5*J5)*0.00007,2),0),"") -> 0.23 | M5: =IF(G5<>0,IF(AND(K5<>"",L5<>"",G5<>"DIVIDEND"),ROUND((K5+L5)*0.07,2),ROUND(H5*0.07,2)),"") -> 0.19 | N5: =IF(F5="cash",0,IF(OR(G5="BUY",G5="SELL"),I5*J5,"")) -> 3250 | O5: =IF(G5<>0,IF(AND(I5<>"",J5<>"",K5<>"",L5<>"",G5="BUY"),(I5*J5)+K5+L5+M5,IF(AND(I5<>"",J5<>"",K5<>"",L5<>"",G5="SELL"),(I5*J5)-(K5+L5+M5),IF(AND(I5<>"",J5<>"",K5<>"",L5<>"",G5="DIVIDEND"),H5-M5,H5))),"") -> 3252.86 | P5: =IF(G5<>0,IF(AND(G5="DEPOSIT",F5="cash"),H5+P4,IF(AND(G5="TRANSFER_TO_BROKER",F5="cash"),P4-H5,IF(AND(G5="DIVIDEND",F5<>""),H5+P4,P4))),"") -> 0 | Q5: =IF(F5<>0,IF(G5<>"",IF(G5="TRANSFER_TO_BROKER",H5+Q4,IF(G5="BUY", Q4-O5,IF(G5="SELL", O5+Q4,IF(G5="TRANSFER_TO_BANK",Q4-H5,Q4)))), ""),"") -> 296.76
A6: =tbl_transactions[[#This Row],[Transaction ID]] -> TH-005 | B6: =tbl_transactions[[#This Row],[Date]] -> 45883 | C6: =tbl_transactions[[#This Row],[Market]] -> set | D6: =tbl_transactions[[#This Row],[Account]] -> 1383357 | E6: =tbl_transactions[[#This Row],[Sequence]] -> 5 | F6: =tbl_transactions[[#This Row],[Asset]] -> SIRI | G6: =tbl_transactions[[#This Row],[Action]] -> BUY | H6: =Transaction_Log!H5 -> 0 | I6: =tbl_transactions[[#This Row],[Quantity]] -> 100 | J6: =tbl_transactions[[#This Row],[Price]] -> 1.53 | K6: =IF(G6<>0,IF(OR(G6="BUY",G6="SELL"),ROUND((I6*J6)*0.00075,2),0),"") -> 0.11 | L6: =IF(G6<>0,IF(OR(G6="BUY",G6="SELL"),ROUND((I6*J6)*0.00007,2),0),"") -> 0.01 | M6: =IF(G6<>0,IF(AND(K6<>"",L6<>"",G6<>"DIVIDEND"),ROUND((K6+L6)*0.07,2),ROUND(H6*0.07,2)),"") -> 0.01 | N6: =IF(F6="cash",0,IF(OR(G6="BUY",G6="SELL"),I6*J6,"")) -> 153 | O6: =IF(G6<>0,IF(AND(I6<>"",J6<>"",K6<>"",L6<>"",G6="BUY"),(I6*J6)+K6+L6+M6,IF(AND(I6<>"",J6<>"",K6<>"",L6<>"",G6="SELL"),(I6*J6)-(K6+L6+M6),IF(AND(I6<>"",J6<>"",K6<>"",L6<>"",G6="DIVIDEND"),H6-M6,H6))),"") -> 153.13 | P6: =IF(G6<>0,IF(AND(G6="DEPOSIT",F6="cash"),H6+P5,IF(AND(G6="TRANSFER_TO_BROKER",F6="cash"),P5-H6,IF(AND(G6="DIVIDEND",F6<>""),H6+P5,P5))),"") -> 0 | Q6: =IF(F6<>0,IF(G6<>"",IF(G6="TRANSFER_TO_BROKER",H6+Q5,IF(G6="BUY", Q5-O6,IF(G6="SELL", O6+Q5,IF(G6="TRANSFER_TO_BANK",Q5-H6,Q5)))), ""),"") -> 143.63
A7: =tbl_transactions[[#This Row],[Transaction ID]] -> TH-006 | B7: =tbl_transactions[[#This Row],[Date]] -> 45937 | C7: =tbl_transactions[[#This Row],[Market]] -> set | D7: =tbl_transactions[[#This Row],[Account]] -> 1383357 | E7: =tbl_transactions[[#This Row],[Sequence]] -> 6 | F7: =tbl_transactions[[#This Row],[Asset]] -> SIRI | G7: =tbl_transactions[[#This Row],[Action]] -> BUY | H7: =Transaction_Log!H7 -> 0 | I7: =tbl_transactions[[#This Row],[Quantity]] -> 100 | J7: =tbl_transactions[[#This Row],[Price]] -> 1.43 | K7: =IF(G7<>0,IF(OR(G7="BUY",G7="SELL"),ROUND((I7*J7)*0.00075,2),0),"") -> 0.11 | L7: =IF(G7<>0,IF(OR(G7="BUY",G7="SELL"),ROUND((I7*J7)*0.00007,2),0),"") -> 0.01 | M7: =IF(G7<>0,IF(AND(K7<>"",L7<>"",G7<>"DIVIDEND"),ROUND((K7+L7)*0.07,2),ROUND(H7*0.07,2)),"") -> 0.01 | N7: =IF(F7="cash",0,IF(OR(G7="BUY",G7="SELL"),I7*J7,"")) -> 143 | O7: =IF(G7<>0,IF(AND(I7<>"",J7<>"",K7<>"",L7<>"",G7="BUY"),(I7*J7)+K7+L7+M7,IF(AND(I7<>"",J7<>"",K7<>"",L7<>"",G7="SELL"),(I7*J7)-(K7+L7+M7),IF(AND(I7<>"",J7<>"",K7<>"",L7<>"",G7="DIVIDEND"),H7-M7,H7))),"") -> 143.13 | P7: =IF(G7<>0,IF(AND(G7="DEPOSIT",F7="cash"),H7+P6,IF(AND(G7="TRANSFER_TO_BROKER",F7="cash"),P6-H7,IF(AND(G7="DIVIDEND",F7<>""),H7+P6,P6))),"") -> 0 | Q7: =IF(F7<>0,IF(G7<>"",IF(G7="TRANSFER_TO_BROKER",H7+Q6,IF(G7="BUY", Q6-O7,IF(G7="SELL", O7+Q6,IF(G7="TRANSFER_TO_BANK",Q6-H7,Q6)))), ""),"") -> 0.5
A8: =tbl_transactions[[#This Row],[Transaction ID]] -> TH-007 | B8: =tbl_transactions[[#This Row],[Date]] -> 45947 | C8: =tbl_transactions[[#This Row],[Market]] -> set | D8: =tbl_transactions[[#This Row],[Account]] -> 0 | E8: =tbl_transactions[[#This Row],[Sequence]] -> 7 | F8: =tbl_transactions[[#This Row],[Asset]] -> PTT | G8: =tbl_transactions[[#This Row],[Action]] -> DIVIDEND | H8: =Transaction_Log!H8 -> 90 | I8: =tbl_transactions[[#This Row],[Quantity]] -> 0 | J8: =tbl_transactions[[#This Row],[Price]] -> 0 | K8: =IF(G8<>0,IF(OR(G8="BUY",G8="SELL"),ROUND((I8*J8)*0.00075,2),0),"") -> 0 | L8: =IF(G8<>0,IF(OR(G8="BUY",G8="SELL"),ROUND((I8*J8)*0.00007,2),0),"") -> 0 | M8: =IF(G8<>0,IF(AND(K8<>"",L8<>"",G8<>"DIVIDEND"),ROUND((K8+L8)*0.07,2),ROUND(H8*0.07,2)),"") -> 6.3 | N8: =IF(F8="cash",0,IF(OR(G8="BUY",G8="SELL"),I8*J8,"")) | O8: =IF(G8<>0,IF(AND(I8<>"",J8<>"",K8<>"",L8<>"",G8="BUY"),(I8*J8)+K8+L8+M8,IF(AND(I8<>"",J8<>"",K8<>"",L8<>"",G8="SELL"),(I8*J8)-(K8+L8+M8),IF(AND(I8<>"",J8<>"",K8<>"",L8<>"",G8="DIVIDEND"),H8-M8,H8))),"") -> 83.7 | P8: =IF(G8<>0,IF(AND(G8="DEPOSIT",F8="cash"),H8+P7,IF(AND(G8="TRANSFER_TO_BROKER",F8="cash"),P7-H8,IF(AND(G8="DIVIDEND",F8<>""),H8+P7,P7))),"") -> 90 | Q8: =IF(F8<>0,IF(G8<>"",IF(G8="TRANSFER_TO_BROKER",H8+Q7,IF(G8="BUY", Q7-O8,IF(G8="SELL", O8+Q7,IF(G8="TRANSFER_TO_BANK",Q7-H8,Q7)))), ""),"") -> 0.5
A9: =tbl_transactions[[#This Row],[Transaction ID]] -> TH-008 | B9: =tbl_transactions[[#This Row],[Date]] -> 46140 | C9: =tbl_transactions[[#This Row],[Market]] -> set | D9: =tbl_transactions[[#This Row],[Account]] -> 0 | E9: =tbl_transactions[[#This Row],[Sequence]] -> 8 | F9: =tbl_transactions[[#This Row],[Asset]] -> PTT | G9: =tbl_transactions[[#This Row],[Action]] -> DIVIDEND | H9: =Transaction_Log!H9 -> 140 | I9: =tbl_transactions[[#This Row],[Quantity]] -> 0 | J9: =tbl_transactions[[#This Row],[Price]] -> 0 | K9: =IF(G9<>0,IF(OR(G9="BUY",G9="SELL"),ROUND((I9*J9)*0.00075,2),0),"") -> 0 | L9: =IF(G9<>0,IF(OR(G9="BUY",G9="SELL"),ROUND((I9*J9)*0.00007,2),0),"") -> 0 | M9: =IF(G9<>0,IF(AND(K9<>"",L9<>"",G9<>"DIVIDEND"),ROUND((K9+L9)*0.07,2),ROUND(H9*0.07,2)),"") -> 9.8 | N9: =IF(F9="cash",0,IF(OR(G9="BUY",G9="SELL"),I9*J9,"")) | O9: =IF(G9<>0,IF(AND(I9<>"",J9<>"",K9<>"",L9<>"",G9="BUY"),(I9*J9)+K9+L9+M9,IF(AND(I9<>"",J9<>"",K9<>"",L9<>"",G9="SELL"),(I9*J9)-(K9+L9+M9),IF(AND(I9<>"",J9<>"",K9<>"",L9<>"",G9="DIVIDEND"),H9-M9,H9))),"") -> 130.2 | P9: =IF(G9<>0,IF(AND(G9="DEPOSIT",F9="cash"),H9+P8,IF(AND(G9="TRANSFER_TO_BROKER",F9="cash"),P8-H9,IF(AND(G9="DIVIDEND",F9<>""),H9+P8,P8))),"") -> 230 | Q9: =IF(F9<>0,IF(G9<>"",IF(G9="TRANSFER_TO_BROKER",H9+Q8,IF(G9="BUY", Q8-O9,IF(G9="SELL", O9+Q8,IF(G9="TRANSFER_TO_BANK",Q8-H9,Q8)))), ""),"") -> 0.5
A10: =tbl_transactions[[#This Row],[Transaction ID]] -> TH-009 | B10: =tbl_transactions[[#This Row],[Date]] -> 46188 | C10: =tbl_transactions[[#This Row],[Market]] -> 0 | D10: =tbl_transactions[[#This Row],[Account]] -> 0 | E10: =tbl_transactions[[#This Row],[Sequence]] -> 9 | F10: =tbl_transactions[[#This Row],[Asset]] -> cash | G10: =tbl_transactions[[#This Row],[Action]] -> DEPOSIT | H10: =Transaction_Log!H10 -> 4000 | I10: =tbl_transactions[[#This Row],[Quantity]] -> 0 | J10: =tbl_transactions[[#This Row],[Price]] -> 0 | K10: =IF(G10<>0,IF(OR(G10="BUY",G10="SELL"),ROUND((I10*J10)*0.00075,2),0),"") -> 0 | L10: =IF(G10<>0,IF(OR(G10="BUY",G10="SELL"),ROUND((I10*J10)*0.00007,2),0),"") -> 0 | M10: =IF(G10<>0,IF(AND(K10<>"",L10<>"",G10<>"DIVIDEND"),ROUND((K10+L10)*0.07,2),ROUND(H10*0.07,2)),"") -> 0 | N10: =IF(F10="cash",0,IF(OR(G10="BUY",G10="SELL"),I10*J10,"")) -> 0 | O10: =IF(G10<>0,IF(AND(I10<>"",J10<>"",K10<>"",L10<>"",G10="BUY"),(I10*J10)+K10+L10+M10,IF(AND(I10<>"",J10<>"",K10<>"",L10<>"",G10="SELL"),(I10*J10)-(K10+L10+M10),IF(AND(I10<>"",J10<>"",K10<>"",L10<>"",G10="DIVIDEND"),H10-M10,H10))),"") -> 4000 | P10: =IF(G10<>0,IF(AND(G10="DEPOSIT",F10="cash"),H10+P9,IF(AND(G10="TRANSFER_TO_BROKER",F10="cash"),P9-H10,IF(AND(G10="DIVIDEND",F10<>""),H10+P9,P9))),"") -> 4230 | Q10: =IF(F10<>0,IF(G10<>"",IF(G10="TRANSFER_TO_BROKER",H10+Q9,IF(G10="BUY", Q9-O10,IF(G10="SELL", O10+Q9,IF(G10="TRANSFER_TO_BANK",Q9-H10,Q9)))), ""),"") -> 0.5
A11: =tbl_transactions[[#This Row],[Transaction ID]] -> TH-010 | B11: =tbl_transactions[[#This Row],[Date]] -> 46218 | C11: =tbl_transactions[[#This Row],[Market]] -> 0 | D11: =tbl_transactions[[#This Row],[Account]] -> 0 | E11: =tbl_transactions[[#This Row],[Sequence]] -> 10 | F11: =tbl_transactions[[#This Row],[Asset]] -> cash | G11: =tbl_transactions[[#This Row],[Action]] -> DEPOSIT | H11: =Transaction_Log!H11 -> 4000 | I11: =tbl_transactions[[#This Row],[Quantity]] -> 0 | J11: =tbl_transactions[[#This Row],[Price]] -> 0 | K11: =IF(G11<>0,IF(OR(G11="BUY",G11="SELL"),ROUND((I11*J11)*0.00075,2),0),"") -> 0 | L11: =IF(G11<>0,IF(OR(G11="BUY",G11="SELL"),ROUND((I11*J11)*0.00007,2),0),"") -> 0 | M11: =IF(G11<>0,IF(AND(K11<>"",L11<>"",G11<>"DIVIDEND"),ROUND((K11+L11)*0.07,2),ROUND(H11*0.07,2)),"") -> 0 | N11: =IF(F11="cash",0,IF(OR(G11="BUY",G11="SELL"),I11*J11,"")) -> 0 | O11: =IF(G11<>0,IF(AND(I11<>"",J11<>"",K11<>"",L11<>"",G11="BUY"),(I11*J11)+K11+L11+M11,IF(AND(I11<>"",J11<>"",K11<>"",L11<>"",G11="SELL"),(I11*J11)-(K11+L11+M11),IF(AND(I11<>"",J11<>"",K11<>"",L11<>"",G11="DIVIDEND"),H11-M11,H11))),"") -> 4000 | P11: =IF(G11<>0,IF(AND(G11="DEPOSIT",F11="cash"),H11+P10,IF(AND(G11="TRANSFER_TO_BROKER",F11="cash"),P10-H11,IF(AND(G11="DIVIDEND",F11<>""),H11+P10,P10))),"") -> 8230 | Q11: =IF(F11<>0,IF(G11<>"",IF(G11="TRANSFER_TO_BROKER",H11+Q10,IF(G11="BUY", Q10-O11,IF(G11="SELL", O11+Q10,IF(G11="TRANSFER_TO_BANK",Q10-H11,Q10)))), ""),"") -> 0.5
A12: =tbl_transactions[[#This Row],[Transaction ID]] -> TH-011 | B12: =tbl_transactions[[#This Row],[Date]] -> 46249 | C12: =tbl_transactions[[#This Row],[Market]] -> 0 | D12: =tbl_transactions[[#This Row],[Account]] -> 0 | E12: =tbl_transactions[[#This Row],[Sequence]] -> 11 | F12: =tbl_transactions[[#This Row],[Asset]] -> cash | G12: =tbl_transactions[[#This Row],[Action]] -> DEPOSIT | H12: =Transaction_Log!H12 -> 4000 | I12: =tbl_transactions[[#This Row],[Quantity]] -> 0 | J12: =tbl_transactions[[#This Row],[Price]] -> 0 | K12: =IF(G12<>0,IF(OR(G12="BUY",G12="SELL"),ROUND((I12*J12)*0.00075,2),0),"") -> 0 | L12: =IF(G12<>0,IF(OR(G12="BUY",G12="SELL"),ROUND((I12*J12)*0.00007,2),0),"") -> 0 | M12: =IF(G12<>0,IF(AND(K12<>"",L12<>"",G12<>"DIVIDEND"),ROUND((K12+L12)*0.07,2),ROUND(H12*0.07,2)),"") -> 0 | N12: =IF(F12="cash",0,IF(OR(G12="BUY",G12="SELL"),I12*J12,"")) -> 0 | O12: =IF(G12<>0,IF(AND(I12<>"",J12<>"",K12<>"",L12<>"",G12="BUY"),(I12*J12)+K12+L12+M12,IF(AND(I12<>"",J12<>"",K12<>"",L12<>"",G12="SELL"),(I12*J12)-(K12+L12+M12),IF(AND(I12<>"",J12<>"",K12<>"",L12<>"",G12="DIVIDEND"),H12-M12,H12))),"") -> 4000 | P12: =IF(G12<>0,IF(AND(G12="DEPOSIT",F12="cash"),H12+P11,IF(AND(G12="TRANSFER_TO_BROKER",F12="cash"),P11-H12,IF(AND(G12="DIVIDEND",F12<>""),H12+P11,P11))),"") -> 12230 | Q12: =IF(F12<>0,IF(G12<>"",IF(G12="TRANSFER_TO_BROKER",H12+Q11,IF(G12="BUY", Q11-O12,IF(G12="SELL", O12+Q11,IF(G12="TRANSFER_TO_BANK",Q11-H12,Q11)))), ""),"") -> 0.5
A13: =tbl_transactions[[#This Row],[Transaction ID]] -> TH-012 | B13: =tbl_transactions[[#This Row],[Date]] -> 46275 | C13: =tbl_transactions[[#This Row],[Market]] -> set | D13: =tbl_transactions[[#This Row],[Account]] -> 1383357 | E13: =tbl_transactions[[#This Row],[Sequence]] -> 12 | F13: =tbl_transactions[[#This Row],[Asset]] -> PTT | G13: =tbl_transactions[[#This Row],[Action]] -> SELL | H13: =Transaction_Log!H13 -> 0 | I13: =tbl_transactions[[#This Row],[Quantity]] -> 100 | J13: =tbl_transactions[[#This Row],[Price]] -> 41.75 | K13: =IF(G13<>0,IF(OR(G13="BUY",G13="SELL"),ROUND((I13*J13)*0.00075,2),0),"") -> 3.13 | L13: =IF(G13<>0,IF(OR(G13="BUY",G13="SELL"),ROUND((I13*J13)*0.00007,2),0),"") -> 0.29 | M13: =IF(G13<>0,IF(AND(K13<>"",L13<>"",G13<>"DIVIDEND"),ROUND((K13+L13)*0.07,2),ROUND(H13*0.07,2)),"") -> 0.24 | N13: =IF(F13="cash",0,IF(OR(G13="BUY",G13="SELL"),I13*J13,"")) -> 4175 | O13: =IF(G13<>0,IF(AND(I13<>"",J13<>"",K13<>"",L13<>"",G13="BUY"),(I13*J13)+K13+L13+M13,IF(AND(I13<>"",J13<>"",K13<>"",L13<>"",G13="SELL"),(I13*J13)-(K13+L13+M13),IF(AND(I13<>"",J13<>"",K13<>"",L13<>"",G13="DIVIDEND"),H13-M13,H13))),"") -> 4171.34 | P13: =IF(G13<>0,IF(AND(G13="DEPOSIT",F13="cash"),H13+P12,IF(AND(G13="TRANSFER_TO_BROKER",F13="cash"),P12-H13,IF(AND(G13="DIVIDEND",F13<>""),H13+P12,P12))),"") -> 12230 | Q13: =IF(F13<>0,IF(G13<>"",IF(G13="TRANSFER_TO_BROKER",H13+Q12,IF(G13="BUY", Q12-O13,IF(G13="SELL", O13+Q12,IF(G13="TRANSFER_TO_BANK",Q12-H13,Q12)))), ""),"") -> 4171.84
A14: =tbl_transactions[[#This Row],[Transaction ID]] -> TH-013 | B14: =tbl_transactions[[#This Row],[Date]] -> 46269 | C14: =tbl_transactions[[#This Row],[Market]] -> set | D14: =tbl_transactions[[#This Row],[Account]] -> 1383357 | E14: =tbl_transactions[[#This Row],[Sequence]] -> 13 | F14: =tbl_transactions[[#This Row],[Asset]] -> KCG | G14: =tbl_transactions[[#This Row],[Action]] -> BUY | H14: =Transaction_Log!H14 -> 0 | I14: =tbl_transactions[[#This Row],[Quantity]] -> 400 | J14: =tbl_transactions[[#This Row],[Price]] -> 10 | K14: =IF(G14<>0,IF(OR(G14="BUY",G14="SELL"),ROUND((I14*J14)*0.00075,2),0),"") -> 3 | L14: =IF(G14<>0,IF(OR(G14="BUY",G14="SELL"),ROUND((I14*J14)*0.00007,2),0),"") -> 0.28 | M14: =IF(G14<>0,IF(AND(K14<>"",L14<>"",G14<>"DIVIDEND"),ROUND((K14+L14)*0.07,2),ROUND(H14*0.07,2)),"") -> 0.23 | N14: =IF(F14="cash",0,IF(OR(G14="BUY",G14="SELL"),I14*J14,"")) -> 4000 | O14: =IF(G14<>0,IF(AND(I14<>"",J14<>"",K14<>"",L14<>"",G14="BUY"),(I14*J14)+K14+L14+M14,IF(AND(I14<>"",J14<>"",K14<>"",L14<>"",G14="SELL"),(I14*J14)-(K14+L14+M14),IF(AND(I14<>"",J14<>"",K14<>"",L14<>"",G14="DIVIDEND"),H14-M14,H14))),"") -> 4003.51 | P14: =IF(G14<>0,IF(AND(G14="DEPOSIT",F14="cash"),H14+P13,IF(AND(G14="TRANSFER_TO_BROKER",F14="cash"),P13-H14,IF(AND(G14="DIVIDEND",F14<>""),H14+P13,P13))),"") -> 12230 | Q14: =IF(F14<>0,IF(G14<>"",IF(G14="TRANSFER_TO_BROKER",H14+Q13,IF(G14="BUY", Q13-O14,IF(G14="SELL", O14+Q13,IF(G14="TRANSFER_TO_BANK",Q13-H14,Q13)))), ""),"") -> 168.33
A15: =tbl_transactions[[#This Row],[Transaction ID]] -> TH-014 | B15: =tbl_transactions[[#This Row],[Date]] -> 46276 | C15: =tbl_transactions[[#This Row],[Market]] -> set | D15: =tbl_transactions[[#This Row],[Account]] -> 0 | E15: =tbl_transactions[[#This Row],[Sequence]] -> 14 | F15: =tbl_transactions[[#This Row],[Asset]] -> SIRI | G15: =tbl_transactions[[#This Row],[Action]] -> DIVIDEND | H15: =Transaction_Log!H15 -> 22.5 | I15: =tbl_transactions[[#This Row],[Quantity]] -> 0 | J15: =tbl_transactions[[#This Row],[Price]] -> 0 | K15: =IF(G15<>0,IF(OR(G15="BUY",G15="SELL"),ROUND((I15*J15)*0.00075,2),0),"") -> 0 | L15: =IF(G15<>0,IF(OR(G15="BUY",G15="SELL"),ROUND((I15*J15)*0.00007,2),0),"") -> 0 | M15: =IF(G15<>0,IF(AND(K15<>"",L15<>"",G15<>"DIVIDEND"),ROUND((K15+L15)*0.07,2),ROUND(H15*0.07,2)),"") -> 1.58 | N15: =IF(F15="cash",0,IF(OR(G15="BUY",G15="SELL"),I15*J15,"")) | O15: =IF(G15<>0,IF(AND(I15<>"",J15<>"",K15<>"",L15<>"",G15="BUY"),(I15*J15)+K15+L15+M15,IF(AND(I15<>"",J15<>"",K15<>"",L15<>"",G15="SELL"),(I15*J15)-(K15+L15+M15),IF(AND(I15<>"",J15<>"",K15<>"",L15<>"",G15="DIVIDEND"),H15-M15,H15))),"") -> 20.92 | P15: =IF(G15<>0,IF(AND(G15="DEPOSIT",F15="cash"),H15+P14,IF(AND(G15="TRANSFER_TO_BROKER",F15="cash"),P14-H15,IF(AND(G15="DIVIDEND",F15<>""),H15+P14,P14))),"") -> 12252.5 | Q15: =IF(F15<>0,IF(G15<>"",IF(G15="TRANSFER_TO_BROKER",H15+Q14,IF(G15="BUY", Q14-O15,IF(G15="SELL", O15+Q14,IF(G15="TRANSFER_TO_BANK",Q14-H15,Q14)))), ""),"") -> 168.33
A16: =tbl_transactions[[#This Row],[Transaction ID]] -> TH-015 | B16: =tbl_transactions[[#This Row],[Date]] -> 46281 | C16: =tbl_transactions[[#This Row],[Market]] -> 0 | D16: =tbl_transactions[[#This Row],[Account]] -> 0 | E16: =tbl_transactions[[#This Row],[Sequence]] -> 15 | F16: =tbl_transactions[[#This Row],[Asset]] -> cash | G16: =tbl_transactions[[#This Row],[Action]] -> DEPOSIT | H16: =Transaction_Log!H16 -> 4000 | I16: =tbl_transactions[[#This Row],[Quantity]] -> 0 | J16: =tbl_transactions[[#This Row],[Price]] -> 0 | K16: =IF(G16<>0,IF(OR(G16="BUY",G16="SELL"),ROUND((I16*J16)*0.00075,2),0),"") -> 0 | L16: =IF(G16<>0,IF(OR(G16="BUY",G16="SELL"),ROUND((I16*J16)*0.00007,2),0),"") -> 0 | M16: =IF(G16<>0,IF(AND(K16<>"",L16<>"",G16<>"DIVIDEND"),ROUND((K16+L16)*0.07,2),ROUND(H16*0.07,2)),"") -> 0 | N16: =IF(F16="cash",0,IF(OR(G16="BUY",G16="SELL"),I16*J16,"")) -> 0 | O16: =IF(G16<>0,IF(AND(I16<>"",J16<>"",K16<>"",L16<>"",G16="BUY"),(I16*J16)+K16+L16+M16,IF(AND(I16<>"",J16<>"",K16<>"",L16<>"",G16="SELL"),(I16*J16)-(K16+L16+M16),IF(AND(I16<>"",J16<>"",K16<>"",L16<>"",G16="DIVIDEND"),H16-M16,H16))),"") -> 4000 | P16: =IF(G16<>0,IF(AND(G16="DEPOSIT",F16="cash"),H16+P15,IF(AND(G16="TRANSFER_TO_BROKER",F16="cash"),P15-H16,IF(AND(G16="DIVIDEND",F16<>""),H16+P15,P15))),"") -> 16252.5 | Q16: =IF(F16<>0,IF(G16<>"",IF(G16="TRANSFER_TO_BROKER",H16+Q15,IF(G16="BUY", Q15-O16,IF(G16="SELL", O16+Q15,IF(G16="TRANSFER_TO_BANK",Q15-H16,Q15)))), ""),"") -> 168.33
A17: =tbl_transactions[[#This Row],[Transaction ID]] -> TH-016 | B17: =tbl_transactions[[#This Row],[Date]] -> 46281 | C17: =tbl_transactions[[#This Row],[Market]] -> 0 | D17: =tbl_transactions[[#This Row],[Account]] -> 0 | E17: =tbl_transactions[[#This Row],[Sequence]] -> 16 | F17: =tbl_transactions[[#This Row],[Asset]] -> cash | G17: =tbl_transactions[[#This Row],[Action]] -> DIVIDEND | H17: =Transaction_Log!H17 -> 91.3 | I17: =tbl_transactions[[#This Row],[Quantity]] -> 0 | J17: =tbl_transactions[[#This Row],[Price]] -> 0 | K17: =IF(G17<>0,IF(OR(G17="BUY",G17="SELL"),ROUND((I17*J17)*0.00075,2),0),"") -> 0 | L17: =IF(G17<>0,IF(OR(G17="BUY",G17="SELL"),ROUND((I17*J17)*0.00007,2),0),"") -> 0 | M17: =IF(G17<>0,IF(AND(K17<>"",L17<>"",G17<>"DIVIDEND"),ROUND((K17+L17)*0.07,2),ROUND(H17*0.07,2)),"") -> 6.39 | N17: =IF(F17="cash",0,IF(OR(G17="BUY",G17="SELL"),I17*J17,"")) -> 0 | O17: =IF(G17<>0,IF(AND(I17<>"",J17<>"",K17<>"",L17<>"",G17="BUY"),(I17*J17)+K17+L17+M17,IF(AND(I17<>"",J17<>"",K17<>"",L17<>"",G17="SELL"),(I17*J17)-(K17+L17+M17),IF(AND(I17<>"",J17<>"",K17<>"",L17<>"",G17="DIVIDEND"),H17-M17,H17))),"") -> 84.91 | P17: =IF(G17<>0,IF(AND(G17="DEPOSIT",F17="cash"),H17+P16,IF(AND(G17="TRANSFER_TO_BROKER",F17="cash"),P16-H17,IF(AND(G17="DIVIDEND",F17<>""),H17+P16,P16))),"") -> 16343.8 | Q17: =IF(F17<>0,IF(G17<>"",IF(G17="TRANSFER_TO_BROKER",H17+Q16,IF(G17="BUY", Q16-O17,IF(G17="SELL", O17+Q16,IF(G17="TRANSFER_TO_BANK",Q16-H17,Q16)))), ""),"") -> 168.33
A18: =tbl_transactions[[#This Row],[Transaction ID]] -> TH-017 | B18: =tbl_transactions[[#This Row],[Date]] -> 46282 | C18: =tbl_transactions[[#This Row],[Market]] -> set | D18: =tbl_transactions[[#This Row],[Account]] -> 1383357 | E18: =tbl_transactions[[#This Row],[Sequence]] -> 17 | F18: =tbl_transactions[[#This Row],[Asset]] -> cash | G18: =tbl_transactions[[#This Row],[Action]] -> TRANSFER_TO_BROKER | H18: =Transaction_Log!H18 -> 16320.8 | I18: =tbl_transactions[[#This Row],[Quantity]] -> 0 | J18: =tbl_transactions[[#This Row],[Price]] -> 0 | K18: =IF(G18<>0,IF(OR(G18="BUY",G18="SELL"),ROUND((I18*J18)*0.00075,2),0),"") -> 0 | L18: =IF(G18<>0,IF(OR(G18="BUY",G18="SELL"),ROUND((I18*J18)*0.00007,2),0),"") -> 0 | M18: =IF(G18<>0,IF(AND(K18<>"",L18<>"",G18<>"DIVIDEND"),ROUND((K18+L18)*0.07,2),ROUND(H18*0.07,2)),"") -> 0 | N18: =IF(F18="cash",0,IF(OR(G18="BUY",G18="SELL"),I18*J18,"")) -> 0 | O18: =IF(G18<>0,IF(AND(I18<>"",J18<>"",K18<>"",L18<>"",G18="BUY"),(I18*J18)+K18+L18+M18,IF(AND(I18<>"",J18<>"",K18<>"",L18<>"",G18="SELL"),(I18*J18)-(K18+L18+M18),IF(AND(I18<>"",J18<>"",K18<>"",L18<>"",G18="DIVIDEND"),H18-M18,H18))),"") -> 16320.8 | P18: =IF(G18<>0,IF(AND(G18="DEPOSIT",F18="cash"),H18+P17,IF(AND(G18="TRANSFER_TO_BROKER",F18="cash"),P17-H18,IF(AND(G18="DIVIDEND",F18<>""),H18+P17,P17))),"") -> 23 | Q18: =IF(F18<>0,IF(G18<>"",IF(G18="TRANSFER_TO_BROKER",H18+Q17,IF(G18="BUY", Q17-O18,IF(G18="SELL", O18+Q17,IF(G18="TRANSFER_TO_BANK",Q17-H18,Q17)))), ""),"") -> 16489.13
A19: =tbl_transactions[[#This Row],[Transaction ID]] -> TH-018 | B19: =tbl_transactions[[#This Row],[Date]] -> 46280 | C19: =tbl_transactions[[#This Row],[Market]] -> 0 | D19: =tbl_transactions[[#This Row],[Account]] -> 0 | E19: =tbl_transactions[[#This Row],[Sequence]] -> 18 | F19: =tbl_transactions[[#This Row],[Asset]] -> cash | G19: =tbl_transactions[[#This Row],[Action]] -> DEPOSIT | H19: =Transaction_Log!H51 -> 0 | I19: =tbl_transactions[[#This Row],[Quantity]] -> 0 | J19: =tbl_transactions[[#This Row],[Price]] -> 0 | K19: =IF(G19<>0,IF(OR(G19="BUY",G19="SELL"),ROUND((I19*J19)*0.00075,2),0),"") -> 0 | L19: =IF(G19<>0,IF(OR(G19="BUY",G19="SELL"),ROUND((I19*J19)*0.00007,2),0),"") -> 0 | M19: =IF(G19<>0,IF(AND(K19<>"",L19<>"",G19<>"DIVIDEND"),ROUND((K19+L19)*0.07,2),ROUND(H19*0.07,2)),"") -> 0 | N19: =IF(F19="cash",0,IF(OR(G19="BUY",G19="SELL"),I19*J19,"")) -> 0 | O19: =IF(G19<>0,IF(AND(I19<>"",J19<>"",K19<>"",L19<>"",G19="BUY"),(I19*J19)+K19+L19+M19,IF(AND(I19<>"",J19<>"",K19<>"",L19<>"",G19="SELL"),(I19*J19)-(K19+L19+M19),IF(AND(I19<>"",J19<>"",K19<>"",L19<>"",G19="DIVIDEND"),H19-M19,H19))),"") -> 0 | P19: =IF(G19<>0,IF(AND(G19="DEPOSIT",F19="cash"),H19+P18,IF(AND(G19="TRANSFER_TO_BROKER",F19="cash"),P18-H19,IF(AND(G19="DIVIDEND",F19<>""),H19+P18,P18))),"") -> 23 | Q19: =IF(F19<>0,IF(G19<>"",IF(G19="TRANSFER_TO_BROKER",H19+Q18,IF(G19="BUY", Q18-O19,IF(G19="SELL", O19+Q18,IF(G19="TRANSFER_TO_BANK",Q18-H19,Q18)))), ""),"") -> 16489.13
A20: =tbl_transactions[[#This Row],[Transaction ID]] -> 0 | B20: =tbl_transactions[[#This Row],[Date]] -> 0 | C20: =tbl_transactions[[#This Row],[Market]] -> 0 | D20: =tbl_transactions[[#This Row],[Account]] -> 0 | E20: =tbl_transactions[[#This Row],[Sequence]] -> 0 | F20: =tbl_transactions[[#This Row],[Asset]] -> 0 | G20: =tbl_transactions[[#This Row],[Action]] -> 0 | H20: =Transaction_Log!H52 -> 0 | I20: =tbl_transactions[[#This Row],[Quantity]] -> 0 | J20: =tbl_transactions[[#This Row],[Price]] -> 0 | K20: =IF(G20<>0,IF(OR(G20="BUY",G20="SELL"),ROUND((I20*J20)*0.00075,2),0),"") | L20: =IF(G20<>0,IF(OR(G20="BUY",G20="SELL"),ROUND((I20*J20)*0.00007,2),0),"") | M20: =IF(G20<>0,IF(AND(K20<>"",L20<>"",G20<>"DIVIDEND"),ROUND((K20+L20)*0.07,2),ROUND(H20*0.07,2)),"") | N20: =IF(F20="cash",0,IF(OR(G20="BUY",G20="SELL"),I20*J20,"")) | O20: =IF(G20<>0,IF(AND(I20<>"",J20<>"",K20<>"",L20<>"",G20="BUY"),(I20*J20)+K20+L20+M20,IF(AND(I20<>"",J20<>"",K20<>"",L20<>"",G20="SELL"),(I20*J20)-(K20+L20+M20),IF(AND(I20<>"",J20<>"",K20<>"",L20<>"",G20="DIVIDEND"),H20-M20,H20))),"") | P20: =IF(G20<>0,IF(AND(G20="DEPOSIT",F20="cash"),H20+P19,IF(AND(G20="TRANSFER_TO_BROKER",F20="cash"),P19-H20,IF(AND(G20="DIVIDEND",F20<>""),H20+P19,P19))),"") | Q20: =IF(F20<>0,IF(G20<>"",IF(G20="TRANSFER_TO_BROKER",H20+Q19,IF(G20="BUY", Q19-O20,IF(G20="SELL", O20+Q19,IF(G20="TRANSFER_TO_BANK",Q19-H20,Q19)))), ""),"")
A21: =tbl_transactions[[#This Row],[Transaction ID]] -> 0 | B21: =tbl_transactions[[#This Row],[Date]] -> 0 | C21: =tbl_transactions[[#This Row],[Market]] -> 0 | D21: =tbl_transactions[[#This Row],[Account]] -> 0 | E21: =tbl_transactions[[#This Row],[Sequence]] -> 0 | F21: =tbl_transactions[[#This Row],[Asset]] -> 0 | G21: =tbl_transactions[[#This Row],[Action]] -> 0 | H21: =Transaction_Log!H53 -> 0 | I21: =tbl_transactions[[#This Row],[Quantity]] -> 0 | J21: =tbl_transactions[[#This Row],[Price]] -> 0 | K21: =IF(G21<>0,IF(OR(G21="BUY",G21="SELL"),ROUND((I21*J21)*0.00075,2),0),"") | L21: =IF(G21<>0,IF(OR(G21="BUY",G21="SELL"),ROUND((I21*J21)*0.00007,2),0),"") | M21: =IF(G21<>0,IF(AND(K21<>"",L21<>"",G21<>"DIVIDEND"),ROUND((K21+L21)*0.07,2),ROUND(H21*0.07,2)),"") | N21: =IF(F21="cash",0,IF(OR(G21="BUY",G21="SELL"),I21*J21,"")) | O21: =IF(G21<>0,IF(AND(I21<>"",J21<>"",K21<>"",L21<>"",G21="BUY"),(I21*J21)+K21+L21+M21,IF(AND(I21<>"",J21<>"",K21<>"",L21<>"",G21="SELL"),(I21*J21)-(K21+L21+M21),IF(AND(I21<>"",J21<>"",K21<>"",L21<>"",G21="DIVIDEND"),H21-M21,H21))),"") | P21: =IF(G21<>0,IF(AND(G21="DEPOSIT",F21="cash"),H21+P20,IF(AND(G21="TRANSFER_TO_BROKER",F21="cash"),P20-H21,IF(AND(G21="DIVIDEND",F21<>""),H21+P20,P20))),"") | Q21: =IF(F21<>0,IF(G21<>"",IF(G21="TRANSFER_TO_BROKER",H21+Q20,IF(G21="BUY", Q20-O21,IF(G21="SELL", O21+Q20,IF(G21="TRANSFER_TO_BANK",Q20-H21,Q20)))), ""),"")
A22: =tbl_transactions[[#This Row],[Transaction ID]] -> 0 | B22: =tbl_transactions[[#This Row],[Date]] -> 0 | C22: =tbl_transactions[[#This Row],[Market]] -> 0 | D22: =tbl_transactions[[#This Row],[Account]] -> 0 | E22: =tbl_transactions[[#This Row],[Sequence]] -> 0 | F22: =tbl_transactions[[#This Row],[Asset]] -> 0 | G22: =tbl_transactions[[#This Row],[Action]] -> 0 | H22: =Transaction_Log!H54 -> 0 | I22: =tbl_transactions[[#This Row],[Quantity]] -> 0 | J22: =tbl_transactions[[#This Row],[Price]] -> 0 | K22: =IF(G22<>0,IF(OR(G22="BUY",G22="SELL"),ROUND((I22*J22)*0.00075,2),0),"") | L22: =IF(G22<>0,IF(OR(G22="BUY",G22="SELL"),ROUND((I22*J22)*0.00007,2),0),"") | M22: =IF(G22<>0,IF(AND(K22<>"",L22<>"",G22<>"DIVIDEND"),ROUND((K22+L22)*0.07,2),ROUND(H22*0.07,2)),"") | N22: =IF(F22="cash",0,IF(OR(G22="BUY",G22="SELL"),I22*J22,"")) | O22: =IF(G22<>0,IF(AND(I22<>"",J22<>"",K22<>"",L22<>"",G22="BUY"),(I22*J22)+K22+L22+M22,IF(AND(I22<>"",J22<>"",K22<>"",L22<>"",G22="SELL"),(I22*J22)-(K22+L22+M22),IF(AND(I22<>"",J22<>"",K22<>"",L22<>"",G22="DIVIDEND"),H22-M22,H22))),"") | P22: =IF(G22<>0,IF(AND(G22="DEPOSIT",F22="cash"),H22+P21,IF(AND(G22="TRANSFER_TO_BROKER",F22="cash"),P21-H22,IF(AND(G22="DIVIDEND",F22<>""),H22+P21,P21))),"") | Q22: =IF(F22<>0,IF(G22<>"",IF(G22="TRANSFER_TO_BROKER",H22+Q21,IF(G22="BUY", Q21-O22,IF(G22="SELL", O22+Q21,IF(G22="TRANSFER_TO_BANK",Q21-H22,Q21)))), ""),"")
A23: =tbl_transactions[[#This Row],[Transaction ID]] -> 0 | B23: =tbl_transactions[[#This Row],[Date]] -> 0 | C23: =tbl_transactions[[#This Row],[Market]] -> 0 | D23: =tbl_transactions[[#This Row],[Account]] -> 0 | E23: =tbl_transactions[[#This Row],[Sequence]] -> 0 | F23: =tbl_transactions[[#This Row],[Asset]] -> 0 | G23: =tbl_transactions[[#This Row],[Action]] -> 0 | H23: =Transaction_Log!H55 -> 0 | I23: =tbl_transactions[[#This Row],[Quantity]] -> 0 | J23: =tbl_transactions[[#This Row],[Price]] -> 0 | K23: =IF(G23<>0,IF(OR(G23="BUY",G23="SELL"),ROUND((I23*J23)*0.00075,2),0),"") | L23: =IF(G23<>0,IF(OR(G23="BUY",G23="SELL"),ROUND((I23*J23)*0.00007,2),0),"") | M23: =IF(G23<>0,IF(AND(K23<>"",L23<>"",G23<>"DIVIDEND"),ROUND((K23+L23)*0.07,2),ROUND(H23*0.07,2)),"") | N23: =IF(F23="cash",0,IF(OR(G23="BUY",G23="SELL"),I23*J23,"")) | O23: =IF(G23<>0,IF(AND(I23<>"",J23<>"",K23<>"",L23<>"",G23="BUY"),(I23*J23)+K23+L23+M23,IF(AND(I23<>"",J23<>"",K23<>"",L23<>"",G23="SELL"),(I23*J23)-(K23+L23+M23),IF(AND(I23<>"",J23<>"",K23<>"",L23<>"",G23="DIVIDEND"),H23-M23,H23))),"") | P23: =IF(G23<>0,IF(AND(G23="DEPOSIT",F23="cash"),H23+P22,IF(AND(G23="TRANSFER_TO_BROKER",F23="cash"),P22-H23,IF(AND(G23="DIVIDEND",F23<>""),H23+P22,P22))),"") | Q23: =IF(F23<>0,IF(G23<>"",IF(G23="TRANSFER_TO_BROKER",H23+Q22,IF(G23="BUY", Q22-O23,IF(G23="SELL", O23+Q22,IF(G23="TRANSFER_TO_BANK",Q22-H23,Q22)))), ""),"")
A24: =tbl_transactions[[#This Row],[Transaction ID]] -> 0 | B24: =tbl_transactions[[#This Row],[Date]] -> 0 | C24: =tbl_transactions[[#This Row],[Market]] -> 0 | D24: =tbl_transactions[[#This Row],[Account]] -> 0 | E24: =tbl_transactions[[#This Row],[Sequence]] -> 0 | F24: =tbl_transactions[[#This Row],[Asset]] -> 0 | G24: =tbl_transactions[[#This Row],[Action]] -> 0 | H24: =Transaction_Log!H56 -> 0 | I24: =tbl_transactions[[#This Row],[Quantity]] -> 0 | J24: =tbl_transactions[[#This Row],[Price]] -> 0 | K24: =IF(G24<>0,IF(OR(G24="BUY",G24="SELL"),ROUND((I24*J24)*0.00075,2),0),"") | L24: =IF(G24<>0,IF(OR(G24="BUY",G24="SELL"),ROUND((I24*J24)*0.00007,2),0),"") | M24: =IF(G24<>0,IF(AND(K24<>"",L24<>"",G24<>"DIVIDEND"),ROUND((K24+L24)*0.07,2),ROUND(H24*0.07,2)),"") | N24: =IF(F24="cash",0,IF(OR(G24="BUY",G24="SELL"),I24*J24,"")) | O24: =IF(G24<>0,IF(AND(I24<>"",J24<>"",K24<>"",L24<>"",G24="BUY"),(I24*J24)+K24+L24+M24,IF(AND(I24<>"",J24<>"",K24<>"",L24<>"",G24="SELL"),(I24*J24)-(K24+L24+M24),IF(AND(I24<>"",J24<>"",K24<>"",L24<>"",G24="DIVIDEND"),H24-M24,H24))),"") | P24: =IF(G24<>0,IF(AND(G24="DEPOSIT",F24="cash"),H24+P23,IF(AND(G24="TRANSFER_TO_BROKER",F24="cash"),P23-H24,IF(AND(G24="DIVIDEND",F24<>""),H24+P23,P23))),"") | Q24: =IF(F24<>0,IF(G24<>"",IF(G24="TRANSFER_TO_BROKER",H24+Q23,IF(G24="BUY", Q23-O24,IF(G24="SELL", O24+Q23,IF(G24="TRANSFER_TO_BANK",Q23-H24,Q23)))), ""),"")
A25: =tbl_transactions[[#This Row],[Transaction ID]] -> 0 | B25: =tbl_transactions[[#This Row],[Date]] -> 0 | C25: =tbl_transactions[[#This Row],[Market]] -> 0 | D25: =tbl_transactions[[#This Row],[Account]] -> 0 | E25: =tbl_transactions[[#This Row],[Sequence]] -> 0 | F25: =tbl_transactions[[#This Row],[Asset]] -> 0 | G25: =tbl_transactions[[#This Row],[Action]] -> 0 | H25: =Transaction_Log!H57 -> 0 | I25: =tbl_transactions[[#This Row],[Quantity]] -> 0 | J25: =tbl_transactions[[#This Row],[Price]] -> 0 | K25: =IF(G25<>0,IF(OR(G25="BUY",G25="SELL"),ROUND((I25*J25)*0.00075,2),0),"") | L25: =IF(G25<>0,IF(OR(G25="BUY",G25="SELL"),ROUND((I25*J25)*0.00007,2),0),"") | M25: =IF(G25<>0,IF(AND(K25<>"",L25<>"",G25<>"DIVIDEND"),ROUND((K25+L25)*0.07,2),ROUND(H25*0.07,2)),"") | N25: =IF(F25="cash",0,IF(OR(G25="BUY",G25="SELL"),I25*J25,"")) | O25: =IF(G25<>0,IF(AND(I25<>"",J25<>"",K25<>"",L25<>"",G25="BUY"),(I25*J25)+K25+L25+M25,IF(AND(I25<>"",J25<>"",K25<>"",L25<>"",G25="SELL"),(I25*J25)-(K25+L25+M25),IF(AND(I25<>"",J25<>"",K25<>"",L25<>"",G25="DIVIDEND"),H25-M25,H25))),"") | P25: =IF(G25<>0,IF(AND(G25="DEPOSIT",F25="cash"),H25+P24,IF(AND(G25="TRANSFER_TO_BROKER",F25="cash"),P24-H25,IF(AND(G25="DIVIDEND",F25<>""),H25+P24,P24))),"") | Q25: =IF(F25<>0,IF(G25<>"",IF(G25="TRANSFER_TO_BROKER",H25+Q24,IF(G25="BUY", Q24-O25,IF(G25="SELL", O25+Q24,IF(G25="TRANSFER_TO_BANK",Q24-H25,Q24)))), ""),"")
A26: =tbl_transactions[[#This Row],[Transaction ID]] -> 0 | B26: =tbl_transactions[[#This Row],[Date]] -> 0 | C26: =tbl_transactions[[#This Row],[Market]] -> 0 | D26: =tbl_transactions[[#This Row],[Account]] -> 0 | E26: =tbl_transactions[[#This Row],[Sequence]] -> 0 | F26: =tbl_transactions[[#This Row],[Asset]] -> 0 | G26: =tbl_transactions[[#This Row],[Action]] -> 0 | H26: =Transaction_Log!H58 -> 0 | I26: =tbl_transactions[[#This Row],[Quantity]] -> 0 | J26: =tbl_transactions[[#This Row],[Price]] -> 0 | K26: =IF(G26<>0,IF(OR(G26="BUY",G26="SELL"),ROUND((I26*J26)*0.00075,2),0),"") | L26: =IF(G26<>0,IF(OR(G26="BUY",G26="SELL"),ROUND((I26*J26)*0.00007,2),0),"") | M26: =IF(G26<>0,IF(AND(K26<>"",L26<>"",G26<>"DIVIDEND"),ROUND((K26+L26)*0.07,2),ROUND(H26*0.07,2)),"") | N26: =IF(F26="cash",0,IF(OR(G26="BUY",G26="SELL"),I26*J26,"")) | O26: =IF(G26<>0,IF(AND(I26<>"",J26<>"",K26<>"",L26<>"",G26="BUY"),(I26*J26)+K26+L26+M26,IF(AND(I26<>"",J26<>"",K26<>"",L26<>"",G26="SELL"),(I26*J26)-(K26+L26+M26),IF(AND(I26<>"",J26<>"",K26<>"",L26<>"",G26="DIVIDEND"),H26-M26,H26))),"") | P26: =IF(G26<>0,IF(AND(G26="DEPOSIT",F26="cash"),H26+P25,IF(AND(G26="TRANSFER_TO_BROKER",F26="cash"),P25-H26,IF(AND(G26="DIVIDEND",F26<>""),H26+P25,P25))),"") | Q26: =IF(F26<>0,IF(G26<>"",IF(G26="TRANSFER_TO_BROKER",H26+Q25,IF(G26="BUY", Q25-O26,IF(G26="SELL", O26+Q25,IF(G26="TRANSFER_TO_BANK",Q25-H26,Q25)))), ""),"")
A27: =tbl_transactions[[#This Row],[Transaction ID]] -> 0 | B27: =tbl_transactions[[#This Row],[Date]] -> 0 | C27: =tbl_transactions[[#This Row],[Market]] -> 0 | D27: =tbl_transactions[[#This Row],[Account]] -> 0 | E27: =tbl_transactions[[#This Row],[Sequence]] -> 0 | F27: =tbl_transactions[[#This Row],[Asset]] -> 0 | G27: =tbl_transactions[[#This Row],[Action]] -> 0 | H27: =Transaction_Log!H59 -> 0 | I27: =tbl_transactions[[#This Row],[Quantity]] -> 0 | J27: =tbl_transactions[[#This Row],[Price]] -> 0 | K27: =IF(G27<>0,IF(OR(G27="BUY",G27="SELL"),ROUND((I27*J27)*0.00075,2),0),"") | L27: =IF(G27<>0,IF(OR(G27="BUY",G27="SELL"),ROUND((I27*J27)*0.00007,2),0),"") | M27: =IF(G27<>0,IF(AND(K27<>"",L27<>"",G27<>"DIVIDEND"),ROUND((K27+L27)*0.07,2),ROUND(H27*0.07,2)),"") | N27: =IF(F27="cash",0,IF(OR(G27="BUY",G27="SELL"),I27*J27,"")) | O27: =IF(G27<>0,IF(AND(I27<>"",J27<>"",K27<>"",L27<>"",G27="BUY"),(I27*J27)+K27+L27+M27,IF(AND(I27<>"",J27<>"",K27<>"",L27<>"",G27="SELL"),(I27*J27)-(K27+L27+M27),IF(AND(I27<>"",J27<>"",K27<>"",L27<>"",G27="DIVIDEND"),H27-M27,H27))),"") | P27: =IF(G27<>0,IF(AND(G27="DEPOSIT",F27="cash"),H27+P26,IF(AND(G27="TRANSFER_TO_BROKER",F27="cash"),P26-H27,IF(AND(G27="DIVIDEND",F27<>""),H27+P26,P26))),"") | Q27: =IF(F27<>0,IF(G27<>"",IF(G27="TRANSFER_TO_BROKER",H27+Q26,IF(G27="BUY", Q26-O27,IF(G27="SELL", O27+Q26,IF(G27="TRANSFER_TO_BANK",Q26-H27,Q26)))), ""),"")
A28: =tbl_transactions[[#This Row],[Transaction ID]] -> 0 | B28: =tbl_transactions[[#This Row],[Date]] -> 0 | C28: =tbl_transactions[[#This Row],[Market]] -> 0 | D28: =tbl_transactions[[#This Row],[Account]] -> 0 | E28: =tbl_transactions[[#This Row],[Sequence]] -> 0 | F28: =tbl_transactions[[#This Row],[Asset]] -> 0 | G28: =tbl_transactions[[#This Row],[Action]] -> 0 | H28: =Transaction_Log!H60 -> 0 | I28: =tbl_transactions[[#This Row],[Quantity]] -> 0 | J28: =tbl_transactions[[#This Row],[Price]] -> 0 | K28: =IF(G28<>0,IF(OR(G28="BUY",G28="SELL"),ROUND((I28*J28)*0.00075,2),0),"") | L28: =IF(G28<>0,IF(OR(G28="BUY",G28="SELL"),ROUND((I28*J28)*0.00007,2),0),"") | M28: =IF(G28<>0,IF(AND(K28<>"",L28<>"",G28<>"DIVIDEND"),ROUND((K28+L28)*0.07,2),ROUND(H28*0.07,2)),"") | N28: =IF(F28="cash",0,IF(OR(G28="BUY",G28="SELL"),I28*J28,"")) | O28: =IF(G28<>0,IF(AND(I28<>"",J28<>"",K28<>"",L28<>"",G28="BUY"),(I28*J28)+K28+L28+M28,IF(AND(I28<>"",J28<>"",K28<>"",L28<>"",G28="SELL"),(I28*J28)-(K28+L28+M28),IF(AND(I28<>"",J28<>"",K28<>"",L28<>"",G28="DIVIDEND"),H28-M28,H28))),"") | P28: =IF(G28<>0,IF(AND(G28="DEPOSIT",F28="cash"),H28+P27,IF(AND(G28="TRANSFER_TO_BROKER",F28="cash"),P27-H28,IF(AND(G28="DIVIDEND",F28<>""),H28+P27,P27))),"") | Q28: =IF(F28<>0,IF(G28<>"",IF(G28="TRANSFER_TO_BROKER",H28+Q27,IF(G28="BUY", Q27-O28,IF(G28="SELL", O28+Q27,IF(G28="TRANSFER_TO_BANK",Q27-H28,Q27)))), ""),"")
A29: =tbl_transactions[[#This Row],[Transaction ID]] -> 0 | B29: =tbl_transactions[[#This Row],[Date]] -> 0 | C29: =tbl_transactions[[#This Row],[Market]] -> 0 | D29: =tbl_transactions[[#This Row],[Account]] -> 0 | E29: =tbl_transactions[[#This Row],[Sequence]] -> 0 | F29: =tbl_transactions[[#This Row],[Asset]] -> 0 | G29: =tbl_transactions[[#This Row],[Action]] -> 0 | H29: =Transaction_Log!H61 -> 0 | I29: =tbl_transactions[[#This Row],[Quantity]] -> 0 | J29: =tbl_transactions[[#This Row],[Price]] -> 0 | K29: =IF(G29<>0,IF(OR(G29="BUY",G29="SELL"),ROUND((I29*J29)*0.00075,2),0),"") | L29: =IF(G29<>0,IF(OR(G29="BUY",G29="SELL"),ROUND((I29*J29)*0.00007,2),0),"") | M29: =IF(G29<>0,IF(AND(K29<>"",L29<>"",G29<>"DIVIDEND"),ROUND((K29+L29)*0.07,2),ROUND(H29*0.07,2)),"") | N29: =IF(F29="cash",0,IF(OR(G29="BUY",G29="SELL"),I29*J29,"")) | O29: =IF(G29<>0,IF(AND(I29<>"",J29<>"",K29<>"",L29<>"",G29="BUY"),(I29*J29)+K29+L29+M29,IF(AND(I29<>"",J29<>"",K29<>"",L29<>"",G29="SELL"),(I29*J29)-(K29+L29+M29),IF(AND(I29<>"",J29<>"",K29<>"",L29<>"",G29="DIVIDEND"),H29-M29,H29))),"") | P29: =IF(G29<>0,IF(AND(G29="DEPOSIT",F29="cash"),H29+P28,IF(AND(G29="TRANSFER_TO_BROKER",F29="cash"),P28-H29,IF(AND(G29="DIVIDEND",F29<>""),H29+P28,P28))),"") | Q29: =IF(F29<>0,IF(G29<>"",IF(G29="TRANSFER_TO_BROKER",H29+Q28,IF(G29="BUY", Q28-O29,IF(G29="SELL", O29+Q28,IF(G29="TRANSFER_TO_BANK",Q28-H29,Q28)))), ""),"")
A30: =tbl_transactions[[#This Row],[Transaction ID]] -> 0 | B30: =tbl_transactions[[#This Row],[Date]] -> 0 | C30: =tbl_transactions[[#This Row],[Market]] -> 0 | D30: =tbl_transactions[[#This Row],[Account]] -> 0 | E30: =tbl_transactions[[#This Row],[Sequence]] -> 0 | F30: =tbl_transactions[[#This Row],[Asset]] -> 0 | G30: =tbl_transactions[[#This Row],[Action]] -> 0 | H30: =Transaction_Log!H62 -> 0 | I30: =tbl_transactions[[#This Row],[Quantity]] -> 0 | J30: =tbl_transactions[[#This Row],[Price]] -> 0 | K30: =IF(G30<>0,IF(OR(G30="BUY",G30="SELL"),ROUND((I30*J30)*0.00075,2),0),"") | L30: =IF(G30<>0,IF(OR(G30="BUY",G30="SELL"),ROUND((I30*J30)*0.00007,2),0),"") | M30: =IF(G30<>0,IF(AND(K30<>"",L30<>"",G30<>"DIVIDEND"),ROUND((K30+L30)*0.07,2),ROUND(H30*0.07,2)),"") | N30: =IF(F30="cash",0,IF(OR(G30="BUY",G30="SELL"),I30*J30,"")) | O30: =IF(G30<>0,IF(AND(I30<>"",J30<>"",K30<>"",L30<>"",G30="BUY"),(I30*J30)+K30+L30+M30,IF(AND(I30<>"",J30<>"",K30<>"",L30<>"",G30="SELL"),(I30*J30)-(K30+L30+M30),IF(AND(I30<>"",J30<>"",K30<>"",L30<>"",G30="DIVIDEND"),H30-M30,H30))),"") | P30: =IF(G30<>0,IF(AND(G30="DEPOSIT",F30="cash"),H30+P29,IF(AND(G30="TRANSFER_TO_BROKER",F30="cash"),P29-H30,IF(AND(G30="DIVIDEND",F30<>""),H30+P29,P29))),"") | Q30: =IF(F30<>0,IF(G30<>"",IF(G30="TRANSFER_TO_BROKER",H30+Q29,IF(G30="BUY", Q29-O30,IF(G30="SELL", O30+Q29,IF(G30="TRANSFER_TO_BANK",Q29-H30,Q29)))), ""),"")
K66: =IF(G66<>"",IF(AND(I66<>"",J66<>""),ROUND((I66*J66)*0.00075,2),0),"") | L66: =IF(G66<>"",IF(AND(I66<>"",J66<>""),ROUND((I66*J66)*0.00007,2),0),"") | M66: =IF(AND(K66<>"",L66<>""),ROUND((K66+L66)*0.07,2),"") | N66: =IF(F66="cash",0,IF(F66<>"",I66*J66,"")) | O66: =IF(G66<>"",IF(AND(I66<>"",J66<>"",K66<>"",L66<>"",G66="BUY"),(I66*J66)+K66+L66+M66,IF(AND(I66<>"",J66<>"",K66<>"",L66<>"",G66="SELL"),(I66*J66)-(K66+L66+M66),H66)),"") | P66: =IF(G66<>"",IF(AND(G66="DEPOSIT",F66="cash"),H66+P65,IF(AND(G66="TRANSFER_TO_BROKER",F66="cash"),P65-H66,IF(AND(G66="DIVIDEND",F66<>""),H66+P65,P65))),"") | Q66: =IF(G66<>"",IF(G66="DEPOSIT_B",H66+Q65,IF(G66="BUY", Q65-O66,IF(G66="SELL", O66+Q65, Q65))), "")
K67: =IF(G67<>"",IF(AND(I67<>"",J67<>""),ROUND((I67*J67)*0.00075,2),0),"") | L67: =IF(G67<>"",IF(AND(I67<>"",J67<>""),ROUND((I67*J67)*0.00007,2),0),"") | M67: =IF(AND(K67<>"",L67<>""),ROUND((K67+L67)*0.07,2),"") | N67: =IF(F67="cash",0,IF(F67<>"",I67*J67,"")) | O67: =IF(G67<>"",IF(AND(I67<>"",J67<>"",K67<>"",L67<>"",G67="BUY"),(I67*J67)+K67+L67+M67,IF(AND(I67<>"",J67<>"",K67<>"",L67<>"",G67="SELL"),(I67*J67)-(K67+L67+M67),H67)),"") | P67: =IF(G67<>"",IF(AND(G67="DEPOSIT",F67="cash"),H67+P66,IF(AND(G67="TRANSFER_TO_BROKER",F67="cash"),P66-H67,IF(AND(G67="DIVIDEND",F67<>""),H67+P66,P66))),"") | Q67: =IF(G67<>"",IF(G67="DEPOSIT_B",H67+Q66,IF(G67="BUY", Q66-O67,IF(G67="SELL", O67+Q66, Q66))), "")
K68: =IF(G68<>"",IF(AND(I68<>"",J68<>""),ROUND((I68*J68)*0.00075,2),0),"") | L68: =IF(G68<>"",IF(AND(I68<>"",J68<>""),ROUND((I68*J68)*0.00007,2),0),"") | M68: =IF(AND(K68<>"",L68<>""),ROUND((K68+L68)*0.07,2),"") | N68: =IF(F68="cash",0,IF(F68<>"",I68*J68,"")) | O68: =IF(G68<>"",IF(AND(I68<>"",J68<>"",K68<>"",L68<>"",G68="BUY"),(I68*J68)+K68+L68+M68,IF(AND(I68<>"",J68<>"",K68<>"",L68<>"",G68="SELL"),(I68*J68)-(K68+L68+M68),H68)),"") | P68: =IF(G68<>"",IF(AND(G68="DEPOSIT",F68="cash"),H68+P67,IF(AND(G68="TRANSFER_TO_BROKER",F68="cash"),P67-H68,IF(AND(G68="DIVIDEND",F68<>""),H68+P67,P67))),"") | Q68: =IF(G68<>"",IF(G68="DEPOSIT_B",H68+Q67,IF(G68="BUY", Q67-O68,IF(G68="SELL", O68+Q67, Q67))), "")
K69: =IF(G69<>"",IF(AND(I69<>"",J69<>""),ROUND((I69*J69)*0.00075,2),0),"") | M69: =IF(AND(K69<>"",L69<>""),ROUND((K69+L69)*0.07,2),"") | N69: =IF(F69="cash",0,IF(F69<>"",I69*J69,"")) | O69: =IF(G69<>"",IF(AND(I69<>"",J69<>"",K69<>"",L69<>"",G69="BUY"),(I69*J69)+K69+L69+M69,IF(AND(I69<>"",J69<>"",K69<>"",L69<>"",G69="SELL"),(I69*J69)-(K69+L69+M69),H69)),"") | P69: =IF(G69<>"",IF(AND(G69="DEPOSIT",F69="cash"),H69+P68,IF(AND(G69="TRANSFER_TO_BROKER",F69="cash"),P68-H69,IF(AND(G69="DIVIDEND",F69<>""),H69+P68,P68))),"") | Q69: =IF(G69<>"",IF(G69="DEPOSIT_B",H69+Q68,IF(G69="BUY", Q68-O69,IF(G69="SELL", O69+Q68, Q68))), "")
K70: =IF(G70<>"",IF(AND(I70<>"",J70<>""),ROUND((I70*J70)*0.00075,2),0),"") | M70: =IF(AND(K70<>"",L70<>""),ROUND((K70+L70)*0.07,2),"") | N70: =IF(F70="cash",0,IF(F70<>"",I70*J70,"")) | O70: =IF(G70<>"",IF(AND(I70<>"",J70<>"",K70<>"",L70<>"",G70="BUY"),(I70*J70)+K70+L70+M70,IF(AND(I70<>"",J70<>"",K70<>"",L70<>"",G70="SELL"),(I70*J70)-(K70+L70+M70),H70)),"") | P70: =IF(G70<>"",IF(AND(G70="DEPOSIT",F70="cash"),H70+P69,IF(AND(G70="TRANSFER_TO_BROKER",F70="cash"),P69-H70,IF(AND(G70="DIVIDEND",F70<>""),H70+P69,P69))),"") | Q70: =IF(G70<>"",IF(G70="DEPOSIT_B",H70+Q69,IF(G70="BUY", Q69-O70,IF(G70="SELL", O70+Q69, Q69))), "")
K71: =IF(G71<>"",IF(AND(I71<>"",J71<>""),ROUND((I71*J71)*0.00075,2),0),"") | M71: =IF(AND(K71<>"",L71<>""),ROUND((K71+L71)*0.07,2),"") | N71: =IF(F71="cash",0,IF(F71<>"",I71*J71,"")) | O71: =IF(G71<>"",IF(AND(I71<>"",J71<>"",K71<>"",L71<>"",G71="BUY"),(I71*J71)+K71+L71+M71,IF(AND(I71<>"",J71<>"",K71<>"",L71<>"",G71="SELL"),(I71*J71)-(K71+L71+M71),H71)),"") | P71: =IF(G71<>"",IF(AND(G71="DEPOSIT",F71="cash"),H71+P70,IF(AND(G71="TRANSFER_TO_BROKER",F71="cash"),P70-H71,IF(AND(G71="DIVIDEND",F71<>""),H71+P70,P70))),"") | Q71: =IF(G71<>"",IF(G71="DEPOSIT_B",H71+Q70,IF(G71="BUY", Q70-O71,IF(G71="SELL", O71+Q70, Q70))), "")
K72: =IF(G72<>"",IF(AND(I72<>"",J72<>""),ROUND((I72*J72)*0.00075,2),0),"") | L72: =IF(G72<>"",IF(AND(I72<>"",J72<>""),ROUND((I72*J72)*0.00007,2),0),"") | M72: =IF(AND(K72<>"",L72<>""),ROUND((K72+L72)*0.07,2),"") | N72: =IF(F72="cash",0,IF(F72<>"",I72*J72,"")) | O72: =IF(G72<>"",IF(AND(I72<>"",J72<>"",K72<>"",L72<>"",G72="BUY"),(I72*J72)+K72+L72+M72,IF(AND(I72<>"",J72<>"",K72<>"",L72<>"",G72="SELL"),(I72*J72)-(K72+L72+M72),H72)),"") | P72: =IF(G72<>"",IF(AND(G72="DEPOSIT",F72="cash"),H72+P71,IF(AND(G72="TRANSFER_TO_BROKER",F72="cash"),P71-H72,IF(AND(G72="DIVIDEND",F72<>""),H72+P71,P71))),"") | Q72: =IF(G72<>"",IF(G72="DEPOSIT_B",H72+Q71,IF(G72="BUY", Q71-O72,IF(G72="SELL", O72+Q71, Q71))), "")
K73: =IF(G73<>"",IF(AND(I73<>"",J73<>""),ROUND((I73*J73)*0.00075,2),0),"") | L73: =IF(G73<>"",IF(AND(I73<>"",J73<>""),ROUND((I73*J73)*0.00007,2),0),"") | M73: =IF(AND(K73<>"",L73<>""),ROUND((K73+L73)*0.07,2),"") | N73: =IF(F73="cash",0,IF(F73<>"",I73*J73,"")) | O73: =IF(G73<>"",IF(AND(I73<>"",J73<>"",K73<>"",L73<>"",G73="BUY"),(I73*J73)+K73+L73+M73,IF(AND(I73<>"",J73<>"",K73<>"",L73<>"",G73="SELL"),(I73*J73)-(K73+L73+M73),H73)),"") | P73: =IF(G73<>"",IF(AND(G73="DEPOSIT",F73="cash"),H73+P72,IF(AND(G73="TRANSFER_TO_BROKER",F73="cash"),P72-H73,IF(AND(G73="DIVIDEND",F73<>""),H73+P72,P72))),"") | Q73: =IF(G73<>"",IF(G73="DEPOSIT_B",H73+Q72,IF(G73="BUY", Q72-O73,IF(G73="SELL", O73+Q72, Q72))), "")
K74: =IF(G74<>"",IF(AND(I74<>"",J74<>""),ROUND((I74*J74)*0.00075,2),0),"") | L74: =IF(G74<>"",IF(AND(I74<>"",J74<>""),ROUND((I74*J74)*0.00007,2),0),"") | M74: =IF(AND(K74<>"",L74<>""),ROUND((K74+L74)*0.07,2),"") | N74: =IF(F74="cash",0,IF(F74<>"",I74*J74,"")) | O74: =IF(G74<>"",IF(AND(I74<>"",J74<>"",K74<>"",L74<>"",G74="BUY"),(I74*J74)+K74+L74+M74,IF(AND(I74<>"",J74<>"",K74<>"",L74<>"",G74="SELL"),(I74*J74)-(K74+L74+M74),H74)),"") | P74: =IF(G74<>"",IF(AND(G74="DEPOSIT",F74="cash"),H74+P73,IF(AND(G74="TRANSFER_TO_BROKER",F74="cash"),P73-H74,IF(AND(G74="DIVIDEND",F74<>""),H74+P73,P73))),"") | Q74: =IF(G74<>"",IF(G74="DEPOSIT_B",H74+Q73,IF(G74="BUY", Q73-O74,IF(G74="SELL", O74+Q73, Q73))), "")
K75: =IF(G75<>"",IF(AND(I75<>"",J75<>""),ROUND((I75*J75)*0.00075,2),0),"") | L75: =IF(G75<>"",IF(AND(I75<>"",J75<>""),ROUND((I75*J75)*0.00007,2),0),"") | M75: =IF(AND(K75<>"",L75<>""),ROUND((K75+L75)*0.07,2),"") | N75: =IF(F75="cash",0,IF(F75<>"",I75*J75,"")) | O75: =IF(G75<>"",IF(AND(I75<>"",J75<>"",K75<>"",L75<>"",G75="BUY"),(I75*J75)+K75+L75+M75,IF(AND(I75<>"",J75<>"",K75<>"",L75<>"",G75="SELL"),(I75*J75)-(K75+L75+M75),H75)),"") | P75: =IF(G75<>"",IF(AND(G75="DEPOSIT",F75="cash"),H75+P74,IF(AND(G75="TRANSFER_TO_BROKER",F75="cash"),P74-H75,IF(AND(G75="DIVIDEND",F75<>""),H75+P74,P74))),"") | Q75: =IF(G75<>"",IF(G75="DEPOSIT_B",H75+Q74,IF(G75="BUY", Q74-O75,IF(G75="SELL", O75+Q74, Q74))), "")
...

Sheet Transaction_Log
A1: Transaction ID | B1: Date | C1: Market | D1: Account | E1: Sequence | F1: Asset | G1: Action | H1: Amount | I1: Quantity | J1: Price
A2: TH-001 | B2: 45873 | E2: 1 | F2: cash | G2: DEPOSIT | H2: 4000
A3: TH-002 | B3: 45877 | D3: 1383357 | E3: 2 | F3: cash | G3: TRANSFER_TO_BROKER | H3: 4000
A4: TH-003 | B4: 45877 | C4: set | D4: 1383357 | E4: 3 | F4: SIRI | G4: BUY | I4: 300 | J4: 1.5
A5: TH-004 | B5: 45882 | C5: set | D5: 1383357 | E5: 4 | F5: PTT | G5: BUY | I5: 100 | J5: 32.5
A6: TH-005 | B6: 45883 | C6: set | D6: 1383357 | E6: 5 | F6: SIRI | G6: BUY | I6: 100 | J6: 1.53
A7: TH-006 | B7: 45937 | C7: set | D7: 1383357 | E7: 6 | F7: SIRI | G7: BUY | I7: 100 | J7: 1.43
A8: TH-007 | B8: 45947 | C8: set | E8: 7 | F8: PTT | G8: DIVIDEND | H8: 90
A9: TH-008 | B9: 46140 | C9: set | E9: 8 | F9: PTT | G9: DIVIDEND | H9: 140
A10: TH-009 | B10: 46188 | E10: 9 | F10: cash | G10: DEPOSIT | H10: 4000
A11: TH-010 | B11: 46218 | E11: 10 | F11: cash | G11: DEPOSIT | H11: 4000
A12: TH-011 | B12: 46249 | E12: 11 | F12: cash | G12: DEPOSIT | H12: 4000
A13: TH-012 | B13: 46275 | C13: set | D13: 1383357 | E13: 12 | F13: PTT | G13: SELL | I13: 100 | J13: 41.75
A14: TH-013 | B14: 46269 | C14: set | D14: 1383357 | E14: 13 | F14: KCG | G14: BUY | I14: 400 | J14: 10
A15: TH-014 | B15: 46276 | C15: set | E15: 14 | F15: SIRI | G15: DIVIDEND | H15: 22.5
A16: TH-015 | B16: 46281 | E16: 15 | F16: cash | G16: DEPOSIT | H16: 4000
A17: TH-016 | B17: 46281 | E17: 16 | F17: cash | G17: DIVIDEND | H17: 91.3
A18: TH-017 | B18: 46282 | C18: set | D18: 1383357 | E18: 17 | F18: cash | G18: TRANSFER_TO_BROKER | H18: 16320.8
A19: TH-018 | B19: 46280 | E19: 18 | F19: cash | G19: DEPOSIT | H19: 4000
